<?xml version="1.0" ?>
<robot name="Cygnus" xmlns:xacro="http://www.ros.org/wiki/xacro" >

  <!-- Import all Gazebo-customization elements, including Gazebo colors -->
  <xacro:include filename="$(find cygnus_description)/model/cygnus.gazebo" />
  
  <gazebo>
      <static>false</static>
  </gazebo>

  <link name="base_link"></link>
  <joint name="random_joint" type="fixed">
    <parent link="base_link"/>
    <child link="Cygnus_Cuerpo"/>
    <origin rpy="0  0  0" xyz="0 0 0"/>
    <axis xyz="0  0  0"/>
  </joint>


  <link name="Cygnus_Cuerpo">
    <inertial>
      <mass value="1.058"/>
      <origin rpy="0  0  0" xyz="0   0   0.01"/>
      <inertia ixx="0.0052239" ixy="0.00018965" ixz="0.00005" iyy="0.0053164" iyz="-0.00004588" izz="0.0089147"/>
    </inertial>
    <collision name="Cygnus__collision">
      <origin rpy="0  0  0" xyz="0   0   0.01"/>
      <geometry>
        <mesh filename="package://cygnus_description/meshes/Cuerpo.dae" scale="0.01 0.01 0.01"/>
      </geometry>
    </collision>
    <visual name="Cygnus__visual">
      <origin rpy="0  0  0" xyz="0   0   0.01"/>
      <geometry>
        <mesh filename="package://cygnus_description/meshes/Cuerpo.dae" scale="0.01 0.01 0.01"/>
      </geometry>
    </visual>
  </link>

  <link name="Cygnus_Motor_1">
    <inertial>
      <mass value="0.074"/>
      <origin rpy="0  0  0" xyz="0 0 0"/>
      <inertia ixx="0.009356" ixy="-0.000004" ixz="-0.000163" iyy="0.009593" iyz="0.000000002" izz="0.007235"/>
    </inertial>
    <collision name="Cygnus__collision">
      <origin rpy="0  0  0" xyz="0 0 0"/>
      <geometry>
        <mesh filename="package://cygnus_description/meshes/motor1.dae" scale="0.01 0.01 0.01"/>
      </geometry>
    </collision>
    <visual name="Cygnus__visual">
      <origin rpy="0  0  0" xyz="0 0 0"/>
      <geometry>
        <mesh filename="package://cygnus_description/meshes/motor1.dae" scale="0.01 0.01 0.01"/>
      </geometry>
    </visual>
  </link>

  <link name="Cygnus_Motor_2">
    <inertial>
      <mass value="0.074"/>
      <origin rpy="0  0  0" xyz="0 0 0"/>
      <inertia ixx="0.009356" ixy="-0.000004" ixz="-0.000163" iyy="0.009593" iyz="0.000000002" izz="0.007235"/>
    </inertial>
    <collision name="Cygnus__collision">
      <origin rpy="0  0  0" xyz="0 0 0"/>
      <geometry>
        <mesh filename="package://cygnus_description/meshes/motor2.dae" scale="0.01 0.01 0.01"/>
      </geometry>
    </collision>
    <visual name="Cygnus__visual">
      <origin rpy="0  0  0" xyz="0 0 0"/>
      <geometry>
        <mesh filename="package://cygnus_description/meshes/motor2.dae" scale="0.01 0.01 0.01"/>
      </geometry>
    </visual>
  </link>

  <link name="Cygnus_Motor_3">
    <inertial>
      <mass value="0.074"/>
      <origin rpy="0  0  0" xyz="0  0    0"/>
      <inertia ixx="0.009356" ixy="-0.000004" ixz="-0.000163" iyy="0.009593" iyz="0.000000002" izz="0.007235"/>
    </inertial>
    <collision name="Cygnus__collision">
      <origin rpy="0  0  0" xyz="0  0    0"/>
      <geometry>
        <mesh filename="package://cygnus_description/meshes/motor3.dae" scale="0.01 0.01 0.01"/>
      </geometry>
    </collision>
    <visual name="Cygnus__visual">
      <origin rpy="0  0  0" xyz="0  0    0"/>
      <geometry>
        <mesh filename="package://cygnus_description/meshes/motor3.dae" scale="0.01 0.01 0.01"/>
      </geometry>
    </visual>
  </link>

  <link name="Cygnus_Motor_4">
    <inertial>
      <mass value="0.074"/>
      <origin rpy="0  0  0" xyz="0  0    0"/>
      <inertia ixx="0.009356" ixy="-0.000004" ixz="-0.000163" iyy="0.009593" iyz="0.000000002" izz="0.007235"/>
    </inertial>
    <collision name="Cygnus__collision">
      <origin rpy="0  0  0" xyz="0  0    0"/>
      <geometry>
        <mesh filename="package://cygnus_description/meshes/motor4.dae" scale="0.01 0.01 0.01"/>
      </geometry>
    </collision>
    <visual name="Cygnus__visual">
      <origin rpy="0  0  0" xyz="0  0    0"/>
      <geometry>
        <mesh filename="package://cygnus_description/meshes/motor4.dae" scale="0.01 0.01 0.01"/>
      </geometry>
    </visual>
  </link>


<joint name="Cygnus_cuerpo_motor1" type="fixed">
    <parent link="Cygnus_Cuerpo"/>
    <child link="Cygnus_Motor_1"/>
    <origin rpy="0  0  0" xyz="0.224874 0 0.027"/>
    <axis xyz="0  0  0"/>
    <limit effort="0" lower="0" upper="0" velocity="0"/>
  </joint>

  <joint name="Cygnus_cuerpo_motor2" type="fixed">
    <parent link="Cygnus_Cuerpo"/>
    <child link="Cygnus_Motor_2"/>
    <origin rpy="0  0  0" xyz="-0.224874 0 0.027"/>
    <axis xyz="0  0  0"/>
    <limit effort="0" lower="0" upper="0" velocity="0"/>
  </joint>

  <joint name="Cygnus_cuerpo_motor3" type="fixed">
    <parent link="Cygnus_Cuerpo"/>
    <child link="Cygnus_Motor_3"/>
    <origin rpy="0  0  0" xyz="0     0.224874  0.027"/>
    <axis xyz="0  0  0"/>
    <limit effort="0" lower="0" upper="0" velocity="0"/>
  </joint>

  <joint name="Cygnus_cuerpo_motor4" type="fixed">
    <parent link="Cygnus_Cuerpo"/>
    <child link="Cygnus_Motor_4"/>
    <origin rpy="0  0  0" xyz="0    -0.224874  0.027"/>
    <axis xyz="0  0  0"/>
    <limit effort="0" lower="0" upper="0" velocity="0"/>
  </joint>


  <link name="Cygnus__Aspa_1">
    <inertial>
      <mass value="0.007"/>
      <origin rpy="0  0  0" xyz="0 0  0"/>
      <inertia ixx="0.000017" ixy="0" ixz="0.0000041" iyy="0.000019" iyz="0" izz="0.000001"/>
    </inertial>
    <collision name="Cygnus__collision">
      <origin rpy="0  0  0" xyz="0.0045 -0.002  0.0325"/>
      <geometry>
        <mesh filename="package://cygnus_description/meshes/aspa1.dae" scale="0.01 0.01 0.01"/>
      </geometry>
    </collision>
    <visual name="Cygnus__visual">
      <origin rpy="0  0  0" xyz="0.0045 -0.002  0.0325"/>
      <geometry>
        <mesh filename="package://cygnus_description/meshes/aspa1.dae" scale="0.01 0.01 0.01"/>
      </geometry>
    </visual>
  </link>

  <link name="Cygnus__Aspa_2">
    <inertial>
      <mass value="0.007"/>
      <origin rpy="0  0  0" xyz="0 0   0"/>
      <inertia ixx="0.000017" ixy="0" ixz="0.0000041" iyy="0.000019" iyz="0" izz="0.000001"/>
    </inertial>
    <collision name="Cygnus__collision">
      <origin rpy="0  0  0" xyz="-0.0045 0.005   0.0325"/>
      <geometry>
        <mesh filename="package://cygnus_description/meshes/aspa2.dae" scale="0.01 0.01 0.01"/>
      </geometry>
    </collision>
    <visual name="Cygnus__visual">
      <origin rpy="0  0  0" xyz="-0.0045 0.005   0.0325"/>
      <geometry>
        <mesh filename="package://cygnus_description/meshes/aspa2.dae" scale="0.01 0.01 0.01"/>
      </geometry>
    </visual>
  </link>

  <link name="Cygnus__Aspa_3">
    <inertial>
      <mass value="0.007"/>
      <origin rpy="0  0  0" xyz="0 0 0"/>
      <inertia ixx="0.000017" ixy="0" ixz="0.0000041" iyy="0.000019" iyz="0" izz="0.000001"/>
    </inertial>
    <collision name="Cygnus__collision">
      <origin rpy="0  0  0" xyz="-0.05 0.0235 0.0105"/>
      <geometry>
        <mesh filename="package://cygnus_description/meshes/aspa3_invert.dae" scale="0.01 0.01 0.01"/>
      </geometry>
    </collision>
    <visual name="Cygnus__visual">
      <origin rpy="0  0  0" xyz="-0.05 0.0235 0.0105"/>
      <geometry>
        <mesh filename="package://cygnus_description/meshes/aspa3_invert.dae" scale="0.01 0.01 0.01"/>
      </geometry>
    </visual>
  </link>

  <link name="Cygnus__Aspa_4">
    <inertial>
      <mass value="0.007"/>
      <origin rpy="0  0  0" xyz="0 0 0"/>
      <inertia ixx="0.000017" ixy="0" ixz="0.0000041" iyy="0.000019" iyz="0" izz="0.000001"/>
    </inertial>
    <collision name="Cygnus__collision">
      <origin rpy="0  0  0" xyz="-0.05 0.0235 0.0105"/>
      <geometry>
        <mesh filename="package://cygnus_description/meshes/aspa4_invert.dae" scale="0.01 0.01 0.01"/>
      </geometry>
    </collision>
    <visual name="Cygnus__visual">
      <origin rpy="0  0  0" xyz="-0.05 0.0235 0.0105"/>
      <geometry>
        <mesh filename="package://cygnus_description/meshes/aspa4_invert.dae" scale="0.01 0.01 0.01"/>
      </geometry>
    </visual>
  </link>

<joint name="Cygnus_revo_motor1" type="continuous">
    <parent link="Cygnus_Motor_1"/>
    <child link="Cygnus__Aspa_1"/>
    <origin rpy="0  0  0" xyz="0 0 0.0055"/>
    <axis xyz="0  0  1"/>
    <limit effort="0.01428" velocity="254"/>
  </joint>

  <joint name="Cygnus_revo_motor2" type="continuous">
    <parent link="Cygnus_Motor_2"/>
    <child link="Cygnus__Aspa_2"/>
    <origin rpy="0  0  0" xyz="-0.004 0    0.0055"/>
    <axis xyz="0  0  1"/>
    <limit effort="0.01428" velocity="254"/>
  </joint>

  <joint name="Cygnus_revo_motor3" type="continuous">
    <parent link="Cygnus_Motor_3"/>
    <child link="Cygnus__Aspa_3"/>
    <origin rpy="0  0  0" xyz="0  0    0"/>
    <axis xyz="0  0 -1"/>
    <limit effort="0.01428" velocity="254"/>
  </joint>

  <joint name="Cygnus_revo_motor4" type="continuous">
    <parent link="Cygnus_Motor_4"/>
    <child link="Cygnus__Aspa_4"/>
    <origin rpy="0  0  0" xyz="0   0  0"/>
    <axis xyz="0  0 -1"/>
    <limit effort="0.01428" velocity="254"/>
  </joint>


  <transmission name="tran_motor1">
    <type>transmission_interface/SimpleTransmission</type>
    <joint name="Cygnus_revo_motor1">
      <hardwareInterface>EffortJointInterface</hardwareInterface>
    </joint>
    <actuator name="motor1">
      <hardwareInterface>EffortJointInterface</hardwareInterface>
    </actuator>
  </transmission>


 <transmission name="tran_motor2">
    <type>transmission_interface/SimpleTransmission</type>
    <joint name="Cygnus_revo_motor2">
      <hardwareInterface>PositionJointInterface</hardwareInterface>
    </joint>
    <actuator name="motor2">
      <hardwareInterface>PositionJointInterface</hardwareInterface>
    </actuator>
  </transmission>

  <transmission name="tran_motor3">
    <type>transmission_interface/SimpleTransmission</type>
    <joint name="Cygnus_revo_motor3">
      <hardwareInterface>PositionJointInterface</hardwareInterface>
    </joint>
    <actuator name="motor3">
      <hardwareInterface>PositionJointInterface</hardwareInterface>
    </actuator>
  </transmission>

  <transmission name="tran_motor4">
    <type>transmission_interface/SimpleTransmission</type>
    <joint name="Cygnus_revo_motor4">
      <hardwareInterface>PositionJointInterface</hardwareInterface>
    </joint>
    <actuator name="motor4">
      <hardwareInterface>PositionJointInterface</hardwareInterface>
    </actuator>
  </transmission>


</robot>
