<?xml version="1.0" ?>
<sdf version="1.5">



  <model name="Cygnus">
  <static>false</static>

    <link name="Cuerpo">
      <pose>0 0 0.01 0 0 0</pose>

      <inertial> 
	<mass> 1.058 </mass> 
	<inertia> 
          <ixx>0.0052239</ixx>  
          <ixy>0.00018965</ixy>     
          <ixz>0.00005</ixz>        
          <iyy>0.0053164</iyy>       
          <iyz>-0.00004588</iyz>         
          <izz>0.0.0089147</izz>      
        </inertia>
      </inertial>

      <collision name="collision">
        <geometry>
          <mesh>
            <uri>model://cygnus/meshes/Cuerpo.dae</uri>
            <scale>0.01 0.01 0.01</scale>
          </mesh>
        </geometry>
      </collision>

      <visual name="visual">
        <geometry>
          <mesh>
            <uri>model://cygnus/meshes/Cuerpo.dae</uri>
            <scale>0.01 0.01 0.01</scale>
          </mesh>
        </geometry>
          <material>
	    <ambient>1 0 0 1</ambient>
	    <diffuse>1 0 0 1</diffuse>
	    <specular>0.1 0.1 0.1 1</specular>
	    <emissive>0 0 0 0</emissive>
	  </material>
      </visual>
    </link>

    <link name="Motor_1">
      <pose>0.224874 0 0.028 0 0 0</pose>

      <inertial> 
	<mass> 0.074 </mass> 
      </inertial>

      <collision name="collision">
        <geometry>
          <mesh>
            <uri>model://cygnus/meshes/motor1.dae</uri>
            <scale>0.01 0.01 0.01</scale>
          </mesh>
        </geometry>
      </collision>

      <visual name="visual">
        <geometry>
          <mesh>
            <uri>model://cygnus/meshes/motor1.dae</uri>
            <scale>0.01 0.01 0.01</scale>
          </mesh>
        </geometry>
      </visual>
    </link>

    <link name="Motor_2">
      <pose>-0.224874 0 0.028 0 0 0</pose>

      <inertial> 
	<mass> 0.074 </mass> 
      </inertial>

      <collision name="collision">
        <geometry>
          <mesh>
            <uri>model://cygnus/meshes/motor2.dae</uri>
            <scale>0.01 0.01 0.01</scale>
          </mesh>
        </geometry>
      </collision>

      <visual name="visual">
        <geometry>
          <mesh>
            <uri>model://cygnus/meshes/motor2.dae</uri>
            <scale>0.01 0.01 0.01</scale>
          </mesh>
        </geometry>
      </visual>
    </link>

    <link name="Motor_3">
      <pose>0 0.224874 0.028 0 0 0</pose>

      <inertial> 
	<mass> 0.074 </mass> 
      </inertial>

      <collision name="collision">
        <geometry>
          <mesh>
            <uri>model://cygnus/meshes/motor3.dae</uri>
            <scale>0.01 0.01 0.01</scale>
          </mesh>
        </geometry>
      </collision>

      <visual name="visual">
        <geometry>
          <mesh>
            <uri>model://cygnus/meshes/motor3.dae</uri>
            <scale>0.01 0.01 0.01</scale>
          </mesh>
        </geometry>
      </visual>
    </link>

    <link name="Motor_4">
      <pose>0 -0.224874 0.028 0 0 0</pose>

      <inertial> 
	<mass> 0.074 </mass> 
      </inertial>

      <collision name="collision">
        <geometry>
          <mesh>
            <uri>model://cygnus/meshes/motor4.dae</uri>
            <scale>0.01 0.01 0.01</scale>
          </mesh>
        </geometry>
      </collision>

      <visual name="visual">
        <geometry>
          <mesh>
            <uri>model://cygnus/meshes/motor4.dae</uri>
            <scale>0.01 0.01 0.01</scale>
          </mesh>
        </geometry>
      </visual>
    </link>

    <link name="Aspa_1">
      <pose>0.231874 -0.002 0.0595 0 0 0</pose>

      <inertial> 
	<mass> 0.007 </mass> 
      </inertial>

      <collision name="collision">
        <geometry>
          <mesh>
            <uri>model://cygnus/meshes/aspa1.dae</uri>
            <scale>0.01 0.01 0.01</scale>
          </mesh>
        </geometry>
      </collision>

      <visual name="visual">
        <geometry>
          <mesh>
            <uri>model://cygnus/meshes/aspa1.dae</uri>
            <scale>0.01 0.01 0.01</scale>
          </mesh>
        </geometry>
      </visual>
    </link>

    <link name="Aspa_2">
      <pose>-0.229874 0.002 0.0595 0 0 0</pose>

      <inertial> 
	<mass> 0.007 </mass> 
      </inertial>

      <collision name="collision">
        <geometry>
          <mesh>
            <uri>model://cygnus/meshes/aspa2.dae</uri>
            <scale>0.01 0.01 0.01</scale>
          </mesh>
        </geometry>
      </collision>

      <visual name="visual">
        <geometry>
          <mesh>
            <uri>model://cygnus/meshes/aspa2.dae</uri>
            <scale>0.01 0.01 0.01</scale>
          </mesh>
        </geometry>
      </visual>
    </link>

    <link name="Aspa_3">
      <pose>-0.049 0.247874 0.0375 0 0 0</pose>

      <inertial> 
	<mass> 0.007 </mass> 
      </inertial>

      <collision name="collision">
        <geometry>
          <mesh>
            <uri>model://cygnus/meshes/aspa3_invert.dae</uri>
            <scale>0.01 0.01 0.01</scale>
          </mesh>
        </geometry>
      </collision>

      <visual name="visual">
        <geometry>
          <mesh>
            <uri>model://cygnus/meshes/aspa3_invert.dae</uri>
            <scale>0.01 0.01 0.01</scale>
          </mesh>
        </geometry>
      </visual>
    </link>

    <link name="Aspa_4">
      <pose>-0.049 -0.201874 0.0375 0 0 0</pose>

      <inertial> 
	<mass> 0.007 </mass> 
      </inertial>

      <collision name="collision">
        <geometry>
          <mesh>
            <uri>model://cygnus/meshes/aspa4_invert.dae</uri>
            <scale>0.01 0.01 0.01</scale>
          </mesh>
        </geometry>
      </collision>

      <visual name="visual">
        <geometry>
          <mesh>
            <uri>model://cygnus/meshes/aspa4_invert.dae</uri>
            <scale>0.01 0.01 0.01</scale>
          </mesh>
        </geometry>
      </visual>
    </link>

      <joint type="revolute" name="revo_motor1">
        <pose>-0.006 0.001 0 0 0 0</pose>
        <child>Aspa_1</child>
        <parent>Motor_1</parent>
        <axis>
           <xyz>0 0 1</xyz>
        </axis>
      </joint>

      <joint type="revolute" name="revo_motor2">
        <pose>0.0032 -0.003 0 0 0 0</pose>
        <child>Aspa_2</child>
        <parent>Motor_2</parent>
        <axis>
          <xyz>0 0 1</xyz>
        </axis>
      </joint>

      <joint type="revolute" name="revo_motor3">
        <pose>0.0492 -0.021 0.024 0 0 0</pose>
        <child>Aspa_3</child>
        <parent>Motor_3</parent>
        <axis>
          <xyz>0 0 -1</xyz>
        </axis>
      </joint>

      <joint type="revolute" name="revo_motor4">
        <pose>0.049 -0.0206 0.023 0 0 0</pose>
        <child>Aspa_4</child>
        <parent>Motor_4</parent>
        <axis>
          <xyz>0 0 -1</xyz>
        </axis>
      </joint>


      <joint type="fixed" name="cuerpo_motor1">
        <pose>0 -0.002 0 0 0 0</pose>
        <child>Motor_1</child>
        <parent>Cuerpo</parent>
      </joint>

      <joint type="fixed" name="cuerpo_motor2">
        <pose>0 0.002 0 0 0 0</pose>
        <child>Motor_2</child>
        <parent>Cuerpo</parent>
      </joint>

      <joint type="fixed" name="cuerpo_motor3">
        <pose> 0.002 0 0 0 0 0</pose>
        <child>Motor_3</child>
        <parent>Cuerpo</parent>
      </joint>

      <joint type="fixed" name="cuerpo_motor4">
        <pose>0.002 0 0 0 0 0</pose>
        <child>Motor_4</child>
        <parent>Cuerpo</parent>
      </joint>


  </model>
</sdf>
