<?xml version="1.0" ?>
<robot name="Cygnus" xmlns:xacro="http://www.ros.org/wiki/xacro" >

  <!-- Import all Gazebo-customization elements, including Gazebo colors -->
  <xacro:include filename="$(find cygnus_description)/model/cygnus.gazebo" />

  <xacro:property name="namespace" value="Cygnus" />
  <xacro:property name="motor_constant" value="8.54858e-06" /> <!-- [kg.m/s^2] -->
  <xacro:property name="moment_constant" value="0.016" /> <!-- [m] -->
  <xacro:property name="time_constant_up" value="0.0125" /> <!-- [s] -->
  <xacro:property name="time_constant_down" value="0.025" /> <!-- [s] -->
  <xacro:property name="max_rot_velocity" value="838" /> <!-- [rad/s] -->
  <xacro:property name="sin30" value="0.5" />
  <xacro:property name="cos30" value="0.866025403784" />
  <xacro:property name="sqrt2" value="1.4142135623730951" />
  <xacro:property name="rotor_drag_coefficient" value="8.06428e-05" />
  <xacro:property name="rolling_moment_coefficient" value="0.000001" />
  <xacro:property name="rotor_velocity_slowdown_sim" value="10" />
  
  <gazebo>
      <static>false</static>
  </gazebo>

  <link name="base_link"></link>
  <joint name="random_joint" type="fixed">
    <parent link="base_link"/>
    <child link="Cygnus_Cuerpo"/>
    <origin rpy="0  0  0" xyz="0 0 0"/>
    <axis xyz="0  0  0"/>
  </joint>


  <link name="Cygnus_Cuerpo">
    <inertial>
      <mass value="1.3"/>
      <origin rpy="0  0  0" xyz="0   0   0.01"/>
      <inertia ixx="0.0052239" ixy="0.00018965" ixz="0.00005" iyy="0.0053164" iyz="-0.00004588" izz="0.0089147"/>
    </inertial>
    <collision>
      <origin rpy="0  0  0" xyz="0   0   0.01"/>
      <geometry>
        <box size="0.76 0.76 0.15"/>
        <!-- [m] [m] [m] -->
      </geometry>
    </collision>
    <visual >
      <origin rpy="0  0  0" xyz="0   0   0.01"/>
      <geometry>
        <mesh filename="package://cygnus_description/meshes/cuerpo.dae" scale="1 1 1"/>
      </geometry>
    </visual>
  </link>



  <link name="Cygnus__Aspa_1">
    <inertial>
      <mass value="0.007"/>
      <origin rpy="0  0  0" xyz="0 0  0"/>
      <inertia ixx="0.000017" ixy="0" ixz="0.0000041" iyy="0.000019" iyz="0" izz="0.000001"/>
    </inertial>
    <collision >
      <geometry>
        <cylinder length="0.006" radius="0.1"/>
      </geometry>
    </collision>
    <visual >
      <geometry>
        <mesh filename="package://cygnus_description/meshes/aspa1.dae" scale="0.01 0.01 0.01"/>
      </geometry>
    </visual>
  </link>



  <link name="Cygnus__Aspa_2">
    <inertial>
      <mass value="0.007"/>
      <origin rpy="0  0  0" xyz="0 0   0"/>
      <inertia ixx="0.000017" ixy="0" ixz="0.0000041" iyy="0.000019" iyz="0" izz="0.000001"/>
    </inertial>
    <collision >
      <geometry>
        <cylinder length="0.006" radius="0.1"/>
      </geometry>
    </collision>
    <visual >
      <geometry>
        <mesh filename="package://cygnus_description/meshes/aspa1.dae" scale="0.01 0.01 0.01"/>
      </geometry>
    </visual>
  </link>

  <link name="Cygnus__Aspa_3">
    <inertial>
      <mass value="0.007"/>
      <origin rpy="0  0  0" xyz="0 0 0"/>
      <inertia ixx="0.000017" ixy="0" ixz="0.0000041" iyy="0.000019" iyz="0" izz="0.000001"/>
    </inertial>
    <collision >
      <geometry>
        <cylinder length="0.006" radius="0.1"/>
      </geometry>
    </collision>
    <visual >
      <geometry>
        <mesh filename="package://cygnus_description/meshes/aspa3_4.dae" scale="1 1 1"/>
      </geometry>
    </visual>
  </link>


  <link name="Cygnus__Aspa_4">
    <inertial>
      <mass value="0.007"/>
      <origin rpy="0  0  0" xyz="0 0 0"/>
      <inertia ixx="0.000017" ixy="0" ixz="0.0000041" iyy="0.000019" iyz="0" izz="0.000001"/>
    </inertial>
    <collision >
      <geometry>
        <cylinder length="0.006" radius="0.1"/>
      </geometry>
    </collision>
    <visual>
      <geometry>
        <mesh filename="package://cygnus_description/meshes/aspa3_4.dae" scale="1 1 1"/>
      </geometry>
    </visual>
  </link>


<joint name="Cygnus_revo_motor1" type="continuous">
    <parent link="base_link"/>
    <child link="Cygnus__Aspa_1"/>
    <origin rpy="0  0  0" xyz="0.224 0 0.062"/>
    <axis xyz="0  0  1"/>
    <limit effort="0.01428" velocity="254"/>
  </joint>
<gazebo>
      <plugin name="$uno_motor_model" filename="librotors_gazebo_motor_model.so">
        <robotNamespace>${namespace}</robotNamespace>
        <jointName>Cygnus_revo_motor1</jointName>
        <linkName>Cygnus__Aspa_1</linkName>
        <turningDirection>"ccw"</turningDirection>
        <timeConstantUp>${time_constant_up}</timeConstantUp>
        <timeConstantDown>${time_constant_down}</timeConstantDown>
        <maxRotVelocity>${max_rot_velocity}</maxRotVelocity>
        <motorConstant>${motor_constant}</motorConstant>
        <momentConstant>${moment_constant}</momentConstant>
        <commandSubTopic>gazebo/command/motor_speed</commandSubTopic>
        <motorNumber>1</motorNumber>
        <rotorDragCoefficient>${rotor_drag_coefficient}</rotorDragCoefficient>
        <rollingMomentCoefficient>${rolling_moment_coefficient}</rollingMomentCoefficient>
        <motorSpeedPubTopic>motor_speed/1</motorSpeedPubTopic>
        <rotorVelocitySlowdownSim>${rotor_velocity_slowdown_sim}</rotorVelocitySlowdownSim>
      </plugin>
    </gazebo>

  <joint name="Cygnus_revo_motor3" type="continuous">
    <parent link="base_link"/>
    <child link="Cygnus__Aspa_3"/>
    <origin rpy="0  0  0" xyz="-0.224 0 0.062"/>
    <axis xyz="0  0  1"/>
    <limit effort="0.01428" velocity="254"/>
  </joint>
<gazebo>
      <plugin name="$tres_motor_model" filename="librotors_gazebo_motor_model.so">
        <robotNamespace>${namespace}</robotNamespace>
        <jointName>Cygnus_revo_motor3</jointName>
        <linkName>Cygnus__Aspa_3</linkName>
        <turningDirection>"ccw"</turningDirection>
        <timeConstantUp>${time_constant_up}</timeConstantUp>
        <timeConstantDown>${time_constant_down}</timeConstantDown>
        <maxRotVelocity>${max_rot_velocity}</maxRotVelocity>
        <motorConstant>${motor_constant}</motorConstant>
        <momentConstant>${moment_constant}</momentConstant>
        <commandSubTopic>gazebo/command/motor_speed</commandSubTopic>
        <motorNumber>1</motorNumber>
        <rotorDragCoefficient>${rotor_drag_coefficient}</rotorDragCoefficient>
        <rollingMomentCoefficient>${rolling_moment_coefficient}</rollingMomentCoefficient>
        <motorSpeedPubTopic>motor_speed/3</motorSpeedPubTopic>
        <rotorVelocitySlowdownSim>${rotor_velocity_slowdown_sim}</rotorVelocitySlowdownSim>
      </plugin>
    </gazebo>

  <joint name="Cygnus_revo_motor2" type="continuous">
    <parent link="base_link"/>
    <child link="Cygnus__Aspa_2"/>
    <origin rpy="0  0  0" xyz="0.0 -0.224 0.062"/>
    <axis xyz="0  0 -1"/>
    <limit effort="0.01428" velocity="254"/>
  </joint>
<gazebo>
      <plugin name="$dos_motor_model" filename="librotors_gazebo_motor_model.so">
        <robotNamespace>${namespace}</robotNamespace>
        <jointName>Cygnus_revo_motor2</jointName>
        <linkName>Cygnus__Aspa_2</linkName>
        <turningDirection>"cw"</turningDirection>
        <timeConstantUp>${time_constant_up}</timeConstantUp>
        <timeConstantDown>${time_constant_down}</timeConstantDown>
        <maxRotVelocity>${max_rot_velocity}</maxRotVelocity>
        <motorConstant>${motor_constant}</motorConstant>
        <momentConstant>${moment_constant}</momentConstant>
        <commandSubTopic>gazebo/command/motor_speed</commandSubTopic>
        <motorNumber>1</motorNumber>
        <rotorDragCoefficient>${rotor_drag_coefficient}</rotorDragCoefficient>
        <rollingMomentCoefficient>${rolling_moment_coefficient}</rollingMomentCoefficient>
        <motorSpeedPubTopic>motor_speed/2</motorSpeedPubTopic>
        <rotorVelocitySlowdownSim>${rotor_velocity_slowdown_sim}</rotorVelocitySlowdownSim>
      </plugin>
    </gazebo>

  <joint name="Cygnus_revo_motor4" type="continuous">
    <parent link="base_link"/>
    <child link="Cygnus__Aspa_4"/>
    <origin rpy="0  0  0" xyz="0.0 0.224 0.062"/>
    <axis xyz="0  0 -1"/>
    <limit effort="0.01428" velocity="254"/>
  </joint>
<gazebo>
      <plugin name="$cuatro_motor_model" filename="librotors_gazebo_motor_model.so">
        <robotNamespace>${namespace}</robotNamespace>
        <jointName>Cygnus_revo_motor4</jointName>
        <linkName>Cygnus__Aspa_4</linkName>
        <turningDirection>"cw"</turningDirection>
        <timeConstantUp>${time_constant_up}</timeConstantUp>
        <timeConstantDown>${time_constant_down}</timeConstantDown>
        <maxRotVelocity>${max_rot_velocity}</maxRotVelocity>
        <motorConstant>${motor_constant}</motorConstant>
        <momentConstant>${moment_constant}</momentConstant>
        <commandSubTopic>gazebo/command/motor_speed</commandSubTopic>
        <motorNumber>1</motorNumber>
        <rotorDragCoefficient>${rotor_drag_coefficient}</rotorDragCoefficient>
        <rollingMomentCoefficient>${rolling_moment_coefficient}</rollingMomentCoefficient>
        <motorSpeedPubTopic>motor_speed/4</motorSpeedPubTopic>
        <rotorVelocitySlowdownSim>${rotor_velocity_slowdown_sim}</rotorVelocitySlowdownSim>
      </plugin>
    </gazebo>



</robot>
